Workbook

Sheet Dashboard
A1: License & Subscription Dashboard
A2: Use this page for weekly reviews and customer renewal meetings.
B4: Tracked Items | C4: Total Annual Cost | D4: Last Refresh | E4: Urgent Threshold | F4: EOL Threshold
B5: =COUNTIF(License_Register!$F$2:$F$306,"<>") -> 50 | C5: =SUM(License_Register!$W$2:$W$306) -> 4368.6 | D5: =TODAY() -> 46140 | E5: =Settings!$B$2 -> 30 | F5: =Settings!$B$4 -> 90
B8: Expired | C8: Urgent | D8: Review | E8: Missing Expiry | F8: Active
B9: =COUNTIF(License_Register!$AA$2:$AA$306,"Expired") -> 10 | C9: =COUNTIF(License_Register!$AA$2:$AA$306,"Urgent") -> 7 | D9: =COUNTIF(License_Register!$AA$2:$AA$306,"Review") -> 1 | E9: =COUNTIF(License_Register!$AA$2:$AA$306,"Missing expiry") -> 2 | F9: =COUNTIF(License_Register!$AA$2:$AA$306,"Active") -> 27
B11: Past EOL | C11: EOL Soon | D11: Qty Purchased | E11: Qty In Use | F11: Qty Available
B12: =COUNTIF(License_Register!$AB$2:$AB$306,"Past EOL") -> 1 | C12: =COUNTIF(License_Register!$AB$2:$AB$306,"EOL soon") -> 0 | D12: =SUM(License_Register!$Q$2:$Q$306) -> 27480 | E12: =SUM(License_Register!$R$2:$R$306) -> 7670 | F12: =SUM(License_Register!$S$2:$S$306) -> 19810
A15: Category Summary | D15: Upcoming License Expiry by Month
A16: Category | B16: Count | D16: Month | E16: Count
A17: SSL Certificate | B17: =COUNTIF(License_Register!$C$2:$C$306,A17) -> 2 | D17: =TEXT(EDATE(TODAY(),0),"mmm-yy") -> Apr-26 | E17: =COUNTIFS(License_Register!$M$2:$M$306,">="&EDATE(EOMONTH(TODAY(),-1),0)+1,License_Register!$M$2:$M$306,"<"&EDATE(EOMONTH(TODAY(),-1),1)+1) -> 0
A18: Server Management | B18: =COUNTIF(License_Register!$C$2:$C$306,A18) -> 3 | D18: =TEXT(EDATE(TODAY(),1),"mmm-yy") -> May-26 | E18: =COUNTIFS(License_Register!$M$2:$M$306,">="&EDATE(EOMONTH(TODAY(),-1),1)+1,License_Register!$M$2:$M$306,"<"&EDATE(EOMONTH(TODAY(),-1),2)+1) -> 7
A19: Endpoint Security | B19: =COUNTIF(License_Register!$C$2:$C$306,A19) -> 10 | D19: =TEXT(EDATE(TODAY(),2),"mmm-yy") -> Jun-26 | E19: =COUNTIFS(License_Register!$M$2:$M$306,">="&EDATE(EOMONTH(TODAY(),-1),2)+1,License_Register!$M$2:$M$306,"<"&EDATE(EOMONTH(TODAY(),-1),3)+1) -> 5
A20: Virtualization | B20: =COUNTIF(License_Register!$C$2:$C$306,A20) -> 0 | D20: =TEXT(EDATE(TODAY(),3),"mmm-yy") -> Jul-26 | E20: =COUNTIFS(License_Register!$M$2:$M$306,">="&EDATE(EOMONTH(TODAY(),-1),3)+1,License_Register!$M$2:$M$306,"<"&EDATE(EOMONTH(TODAY(),-1),4)+1) -> 0
A21: Operating System | B21: =COUNTIF(License_Register!$C$2:$C$306,A21) -> 6 | D21: =TEXT(EDATE(TODAY(),4),"mmm-yy") -> Aug-26 | E21: =COUNTIFS(License_Register!$M$2:$M$306,">="&EDATE(EOMONTH(TODAY(),-1),4)+1,License_Register!$M$2:$M$306,"<"&EDATE(EOMONTH(TODAY(),-1),5)+1) -> 0
A22: Network Appliance | B22: =COUNTIF(License_Register!$C$2:$C$306,A22) -> 4 | D22: =TEXT(EDATE(TODAY(),5),"mmm-yy") -> Sep-26 | E22: =COUNTIFS(License_Register!$M$2:$M$306,">="&EDATE(EOMONTH(TODAY(),-1),5)+1,License_Register!$M$2:$M$306,"<"&EDATE(EOMONTH(TODAY(),-1),6)+1) -> 0
A23: Backup | B23: =COUNTIF(License_Register!$C$2:$C$306,A23) -> 2 | D23: =TEXT(EDATE(TODAY(),6),"mmm-yy") -> Oct-26 | E23: =COUNTIFS(License_Register!$M$2:$M$306,">="&EDATE(EOMONTH(TODAY(),-1),6)+1,License_Register!$M$2:$M$306,"<"&EDATE(EOMONTH(TODAY(),-1),7)+1) -> 1
A24: Monitoring | B24: =COUNTIF(License_Register!$C$2:$C$306,A24) -> 13 | D24: =TEXT(EDATE(TODAY(),7),"mmm-yy") -> Nov-26 | E24: =COUNTIFS(License_Register!$M$2:$M$306,">="&EDATE(EOMONTH(TODAY(),-1),7)+1,License_Register!$M$2:$M$306,"<"&EDATE(EOMONTH(TODAY(),-1),8)+1) -> 0
A25: SaaS | B25: =COUNTIF(License_Register!$C$2:$C$306,A25) -> 0 | D25: =TEXT(EDATE(TODAY(),8),"mmm-yy") -> Dec-26 | E25: =COUNTIFS(License_Register!$M$2:$M$306,">="&EDATE(EOMONTH(TODAY(),-1),8)+1,License_Register!$M$2:$M$306,"<"&EDATE(EOMONTH(TODAY(),-1),9)+1) -> 0
A26: Other | B26: =COUNTIF(License_Register!$C$2:$C$306,A26) -> 5 | D26: =TEXT(EDATE(TODAY(),9),"mmm-yy") -> Jan-27 | E26: =COUNTIFS(License_Register!$M$2:$M$306,">="&EDATE(EOMONTH(TODAY(),-1),9)+1,License_Register!$M$2:$M$306,"<"&EDATE(EOMONTH(TODAY(),-1),10)+1) -> 3
D27: =TEXT(EDATE(TODAY(),10),"mmm-yy") -> Feb-27 | E27: =COUNTIFS(License_Register!$M$2:$M$306,">="&EDATE(EOMONTH(TODAY(),-1),10)+1,License_Register!$M$2:$M$306,"<"&EDATE(EOMONTH(TODAY(),-1),11)+1) -> 13
D28: =TEXT(EDATE(TODAY(),11),"mmm-yy") -> Mar-27 | E28: =COUNTIFS(License_Register!$M$2:$M$306,">="&EDATE(EOMONTH(TODAY(),-1),11)+1,License_Register!$M$2:$M$306,"<"&EDATE(EOMONTH(TODAY(),-1),12)+1) -> 4
A29: Recommended review queue
A30: 1) Filter License_Register for Expired, Urgent, Review or Past EOL
A31: 2) Sort Days to Expiry ascending and contact the Renewal Owner
A32: 3) Validate quantity gaps where utilization is high or availability is low
A33: 4) Update Last Reviewed after each customer or internal renewal check

Sheet License_Register
A1: Client | B1: Site / Region | C1: Category | D1: Item Type | E1: Vendor | F1: Product / Service | G1: Asset / Hostname / Scope | H1: Environment | I1: Primary Owner | J1: Technical Contact | K1: License Ref / Serial / Cert CN | L1: Start Date | M1: Expiry Date | N1: Days to Expiry | O1: Renewal Cycle | P1: Auto Renew | Q1: Qty Purchased | R1: Qty In Use | S1: Qty Available | T1: Utilization % | U1: Unit Cost | V1: Currency | W1: Annual Cost | X1: Support / EOL Date | Y1: Days to EOL | Z1: Priority | AA1: License Status | AB1: EOL Status | AC1: Escalation Needed | AD1: Renewal Owner | AE1: Last Reviewed | AF1: Notes | AG1: Source / Portal URL
A2: CPC | B2: HQ | C2: Monitoring | D2: License | E2: OpenText | F2: OBM | G2: TBC | H2: Production | I2: OPS Team | J2: Ayman Makram | K2: TBC | L2: 45319 | M2: 45836 | N2: =IF($F2="","",IF($M2="","",$M2-TODAY())) -> -304 | O2: Annual | P2: No | Q2: 200 | R2: 0 | S2: =IF($F2="","",IF(OR($Q2="",$R2=""),"",$Q2-$R2)) -> 200 | T2: =IF($F2="","",IF(OR($Q2="",$Q2=0,$R2=""),"",$R2/$Q2)) -> 0 | U2: 0 | V2: USD | W2: 2 | Y2: =IF($F2="","",IF($X2="","",$X2-TODAY())) | Z2: High | AA2: =IF($F2="","",IF($M2="","Missing expiry",IF($N2<0,"Expired",IF($N2<=Settings!$B$2,"Urgent",IF($N2<=Settings!$B$3,"Review","Active"))))) -> Expired | AB2: =IF($F2="","",IF($X2="","",IF($Y2<0,"Past EOL",IF($Y2<=Settings!$B$4,"EOL soon","Supported")))) | AC2: =IF($F2="","",IF(OR($AA2="Expired",$AA2="Urgent",$AB2="Past EOL",$AB2="EOL soon"),"Yes","No")) -> Yes | AD2: TAM | AE2: 46118
A3: CPC | B3: HQ | C3: Tickting Solution | D3: License | E3: OpenText | F3: SMAX | G3: TBC | H3: Production | I3: OPS Team | J3: Ayman Makram | K3: TBC | L3: 45836 | M3: 46201 | N3: =IF($F3="","",IF($M3="","",$M3-TODAY())) -> 61 | O3: Annual | P3: No | Q3: 20 | R3: 0 | S3: =IF($F3="","",IF(OR($Q3="",$R3=""),"",$Q3-$R3)) -> 20 | T3: =IF($F3="","",IF(OR($Q3="",$Q3=0,$R3=""),"",$R3/$Q3)) -> 0 | U3: 0 | V3: USD | W3: 2 | Y3: =IF($F3="","",IF($X3="","",$X3-TODAY())) | Z3: High | AA3: =IF($F3="","",IF($M3="","Missing expiry",IF($N3<0,"Expired",IF($N3<=Settings!$B$2,"Urgent",IF($N3<=Settings!$B$3,"Review","Active"))))) -> Active | AB3: =IF($F3="","",IF($X3="","",IF($Y3<0,"Past EOL",IF($Y3<=Settings!$B$4,"EOL soon","Supported")))) | AC3: =IF($F3="","",IF(OR($AA3="Expired",$AA3="Urgent",$AB3="Past EOL",$AB3="EOL soon"),"Yes","No")) -> No | AD3: TAM | AE3: 46118
A4: CPC | B4: HQ | C4: Monitoring | D4: License | E4: OpenText | F4: NOM | G4: TBC | H4: Production | I4: OPS Team | J4: Ayman Makram | K4: TBC | L4: 45837 | M4: 46202 | N4: =IF($F4="","",IF($M4="","",$M4-TODAY())) -> 62 | O4: Annual | P4: No | Q4: 400 | R4: 0 | S4: =IF($F4="","",IF(OR($Q4="",$R4=""),"",$Q4-$R4)) -> 400 | T4: =IF($F4="","",IF(OR($Q4="",$Q4=0,$R4=""),"",$R4/$Q4)) -> 0 | U4: 0 | V4: USD | W4: 1 | Y4: =IF($F4="","",IF($X4="","",$X4-TODAY())) | Z4: High | AA4: =IF($F4="","",IF($M4="","Missing expiry",IF($N4<0,"Expired",IF($N4<=Settings!$B$2,"Urgent",IF($N4<=Settings!$B$3,"Review","Active"))))) -> Active | AB4: =IF($F4="","",IF($X4="","",IF($Y4<0,"Past EOL",IF($Y4<=Settings!$B$4,"EOL soon","Supported")))) | AC4: =IF($F4="","",IF(OR($AA4="Expired",$AA4="Urgent",$AB4="Past EOL",$AB4="EOL soon"),"Yes","No")) -> No | AD4: TAM | AE4: 46118
A5: CPC | B5: HQ | C5: Monitoring | D5: License | E5: OpenText | F5: Vertica | G5: TBC | H5: Production | I5: OPS Team | J5: Ayman Makram | K5: TBC | L5: 45836 | M5: 46199 | N5: =IF($F5="","",IF($M5="","",$M5-TODAY())) -> 59 | O5: Annual | P5: No | Q5: 20 | R5: 0 | S5: =IF($F5="","",IF(OR($Q5="",$R5=""),"",$Q5-$R5)) -> 20 | T5: =IF($F5="","",IF(OR($Q5="",$Q5=0,$R5=""),"",$R5/$Q5)) -> 0 | U5: 0 | V5: USD | W5: 2 | Y5: =IF($F5="","",IF($X5="","",$X5-TODAY())) | Z5: High | AA5: =IF($F5="","",IF($M5="","Missing expiry",IF($N5<0,"Expired",IF($N5<=Settings!$B$2,"Urgent",IF($N5<=Settings!$B$3,"Review","Active"))))) -> Review | AB5: =IF($F5="","",IF($X5="","",IF($Y5<0,"Past EOL",IF($Y5<=Settings!$B$4,"EOL soon","Supported")))) | AC5: =IF($F5="","",IF(OR($AA5="Expired",$AA5="Urgent",$AB5="Past EOL",$AB5="EOL soon"),"Yes","No")) -> No | AD5: TAM | AE5: 46118
A6: CPC | B6: HQ | C6: Monitoring | D6: License | E6: OpenText | F6: SAM | G6: TBC | H6: Production | I6: OPS Team | J6: Ayman Makram | K6: TBC | L6: 45471 | M6: 45835 | N6: =IF($F6="","",IF($M6="","",$M6-TODAY())) -> -305 | O6: Annual | P6: No | Q6: 2900 | R6: 0 | S6: =IF($F6="","",IF(OR($Q6="",$R6=""),"",$Q6-$R6)) -> 2900 | T6: =IF($F6="","",IF(OR($Q6="",$Q6=0,$R6=""),"",$R6/$Q6)) -> 0 | U6: 0.5 | V6: USD | W6: =IF($F6="","",IF(OR($U6="",$Q6=""),"",$U6*$Q6)) -> 1450 | X6: 45209 | Y6: =IF($F6="","",IF($X6="","",$X6-TODAY())) -> -931 | Z6: Critical | AA6: =IF($F6="","",IF($M6="","Missing expiry",IF($N6<0,"Expired",IF($N6<=Settings!$B$2,"Urgent",IF($N6<=Settings!$B$3,"Review","Active"))))) -> Expired | AB6: =IF($F6="","",IF($X6="","",IF($Y6<0,"Past EOL",IF($Y6<=Settings!$B$4,"EOL soon","Supported")))) -> Past EOL | AC6: =IF($F6="","",IF(OR($AA6="Expired",$AA6="Urgent",$AB6="Past EOL",$AB6="EOL soon"),"Yes","No")) -> Yes | AD6: TAM | AE6: 46118
A7: CPC | B7: HQ | C7: Monitoring | D7: License | E7: OpenText | F7: UCMDB | G7: TBC | H7: Production | I7: OPS Team | J7: Ayman Makram | K7: TBC | L7: 45776 | M7: 46202 | N7: =IF($F7="","",IF($M7="","",$M7-TODAY())) -> 62 | O7: Annual | P7: No | Q7: 200 | R7: 0 | S7: =IF($F7="","",IF(OR($Q7="",$R7=""),"",$Q7-$R7)) -> 200 | T7: =IF($F7="","",IF(OR($Q7="",$Q7=0,$R7=""),"",$R7/$Q7)) -> 0 | U7: 0 | V7: USD | W7: =IF($F7="","",IF(OR($U7="",$Q7=""),"",$U7*$Q7)) -> 0 | X7: 46871 | Y7: =IF($F7="","",IF($X7="","",$X7-TODAY())) -> 731 | Z7: High | AA7: =IF($F7="","",IF($M7="","Missing expiry",IF($N7<0,"Expired",IF($N7<=Settings!$B$2,"Urgent",IF($N7<=Settings!$B$3,"Review","Active"))))) -> Active | AB7: =IF($F7="","",IF($X7="","",IF($Y7<0,"Past EOL",IF($Y7<=Settings!$B$4,"EOL soon","Supported")))) -> Supported | AC7: =IF($F7="","",IF(OR($AA7="Expired",$AA7="Urgent",$AB7="Past EOL",$AB7="EOL soon"),"Yes","No")) -> No | AD7: TAM | AE7: 46118
A8: CPC | B8: HQ | C8: Monitoring | D8: License | E8: OpenText | F8: UFT | G8: TBC | H8: Production | I8: OPS Team | J8: Ayman Makram | K8: TBC | L8: 45471 | M8: 45835 | N8: =IF($F8="","",IF($M8="","",$M8-TODAY())) -> -305 | O8: Annual | P8: No | Q8: 5 | R8: 0 | S8: =IF($F8="","",IF(OR($Q8="",$R8=""),"",$Q8-$R8)) -> 5 | T8: =IF($F8="","",IF(OR($Q8="",$Q8=0,$R8=""),"",$R8/$Q8)) -> 0 | V8: USD | W8: 5 | Y8: =IF($F8="","",IF($X8="","",$X8-TODAY())) | Z8: High | AA8: =IF($F8="","",IF($M8="","Missing expiry",IF($N8<0,"Expired",IF($N8<=Settings!$B$2,"Urgent",IF($N8<=Settings!$B$3,"Review","Active"))))) -> Expired | AB8: =IF($F8="","",IF($X8="","",IF($Y8<0,"Past EOL",IF($Y8<=Settings!$B$4,"EOL soon","Supported")))) | AC8: =IF($F8="","",IF(OR($AA8="Expired",$AA8="Urgent",$AB8="Past EOL",$AB8="EOL soon"),"Yes","No")) -> Yes | AD8: TAM | AE8: 46118
A9: CPC | B9: HQ | C9: Monitoring | D9: License | E9: OpenText | F9: Load Runner | G9: TBC | H9: Production | I9: OPS Team | J9: Ayman Makram | K9: TBC | L9: 45471 | M9: 45836 | N9: =IF($F9="","",IF($M9="","",$M9-TODAY())) -> -304 | O9: Annual | P9: No | Q9: 150 | R9: 0 | S9: =IF($F9="","",IF(OR($Q9="",$R9=""),"",$Q9-$R9)) -> 150 | T9: =IF($F9="","",IF(OR($Q9="",$Q9=0,$R9=""),"",$R9/$Q9)) -> 0 | V9: USD | W9: 2 | Y9: =IF($F9="","",IF($X9="","",$X9-TODAY())) | Z9: High | AA9: =IF($F9="","",IF($M9="","Missing expiry",IF($N9<0,"Expired",IF($N9<=Settings!$B$2,"Urgent",IF($N9<=Settings!$B$3,"Review","Active"))))) -> Expired | AB9: =IF($F9="","",IF($X9="","",IF($Y9<0,"Past EOL",IF($Y9<=Settings!$B$4,"EOL soon","Supported")))) | AC9: =IF($F9="","",IF(OR($AA9="Expired",$AA9="Urgent",$AB9="Past EOL",$AB9="EOL soon"),"Yes","No")) -> Yes | AD9: TAM | AE9: 46118
A10: CPC | B10: HQ | C10: Endpoint Security | D10: License | E10: Elastic | F10: EDR | G10: TBC | H10: Production | I10: OPS Team | J10: Ali Mohamed | K10: TBC | L10: 45622 | M10: 46420 | N10: =IF($F10="","",IF($M10="","",$M10-TODAY())) -> 280 | O10: Annual | P10: No | S10: =IF($F10="","",IF(OR($Q10="",$R10=""),"",$Q10-$R10)) | T10: =IF($F10="","",IF(OR($Q10="",$Q10=0,$R10=""),"",$R10/$Q10)) | V10: USD | W10: 1 | Y10: =IF($F10="","",IF($X10="","",$X10-TODAY())) | Z10: High | AA10: =IF($F10="","",IF($M10="","Missing expiry",IF($N10<0,"Expired",IF($N10<=Settings!$B$2,"Urgent",IF($N10<=Settings!$B$3,"Review","Active"))))) -> Active | AB10: =IF($F10="","",IF($X10="","",IF($Y10<0,"Past EOL",IF($Y10<=Settings!$B$4,"EOL soon","Supported")))) | AC10: =IF($F10="","",IF(OR($AA10="Expired",$AA10="Urgent",$AB10="Past EOL",$AB10="EOL soon"),"Yes","No")) -> No | AD10: TAM | AE10: 46118
A11: CPC | B11: HQ | C11: Endpoint Security | D11: License | E11: Elastic | F11: Elastic Backend | G11: TBC | H11: Production | I11: OPS Team | J11: Ali Mohamed | K11: TBC | L11: 45622 | M11: 46420 | N11: =IF($F11="","",IF($M11="","",$M11-TODAY())) -> 280 | O11: Annual | P11: No | Q11: 5 | R11: 3 | S11: =IF($F11="","",IF(OR($Q11="",$R11=""),"",$Q11-$R11)) -> 2 | T11: =IF($F11="","",IF(OR($Q11="",$Q11=0,$R11=""),"",$R11/$Q11)) -> 0.6 | V11: USD | W11: 1 | Y11: =IF($F11="","",IF($X11="","",$X11-TODAY())) | Z11: High | AA11: =IF($F11="","",IF($M11="","Missing expiry",IF($N11<0,"Expired",IF($N11<=Settings!$B$2,"Urgent",IF($N11<=Settings!$B$3,"Review","Active"))))) -> Active | AB11: =IF($F11="","",IF($X11="","",IF($Y11<0,"Past EOL",IF($Y11<=Settings!$B$4,"EOL soon","Supported")))) | AC11: =IF($F11="","",IF(OR($AA11="Expired",$AA11="Urgent",$AB11="Past EOL",$AB11="EOL soon"),"Yes","No")) -> No | AD11: TAM | AE11: 46118
A12: CPC | B12: HQ | C12: Endpoint Security | D12: License | E12: Stack-X | F12: EPM | G12: TBC | H12: Production | I12: OPS Team | J12: Mostafa Mohamed | K12: TBC | L12: 45471 | M12: 45835 | N12: =IF($F12="","",IF($M12="","",$M12-TODAY())) -> -305 | O12: Annual | P12: No | Q12: 2000 | R12: 0 | S12: =IF($F12="","",IF(OR($Q12="",$R12=""),"",$Q12-$R12)) -> 2000 | T12: =IF($F12="","",IF(OR($Q12="",$Q12=0,$R12=""),"",$R12/$Q12)) -> 0 | U12: 0.6 | V12: USD | W12: =IF($F12="","",IF(OR($U12="",$Q12=""),"",$U12*$Q12)) -> 1200 | Y12: =IF($F12="","",IF($X12="","",$X12-TODAY())) | Z12: High | AA12: =IF($F12="","",IF($M12="","Missing expiry",IF($N12<0,"Expired",IF($N12<=Settings!$B$2,"Urgent",IF($N12<=Settings!$B$3,"Review","Active"))))) -> Expired | AB12: =IF($F12="","",IF($X12="","",IF($Y12<0,"Past EOL",IF($Y12<=Settings!$B$4,"EOL soon","Supported")))) | AC12: =IF($F12="","",IF(OR($AA12="Expired",$AA12="Urgent",$AB12="Past EOL",$AB12="EOL soon"),"Yes","No")) -> Yes | AD12: TAM | AE12: 46118
A13: CPC | B13: HQ | C13: Server Management | D13: License | E13: Stack-X | F13: Server Management | G13: TBC | H13: Production | I13: OPS Team | J13: Mostafa Mohamed | K13: TBC | L13: 45471 | M13: 45835 | N13: =IF($F13="","",IF($M13="","",$M13-TODAY())) -> -305 | O13: Annual | P13: No | Q13: 200 | R13: 0 | S13: =IF($F13="","",IF(OR($Q13="",$R13=""),"",$Q13-$R13)) -> 200 | T13: =IF($F13="","",IF(OR($Q13="",$Q13=0,$R13=""),"",$R13/$Q13)) -> 0 | V13: USD | W13: 0.6 | Y13: =IF($F13="","",IF($X13="","",$X13-TODAY())) | Z13: High | AA13: =IF($F13="","",IF($M13="","Missing expiry",IF($N13<0,"Expired",IF($N13<=Settings!$B$2,"Urgent",IF($N13<=Settings!$B$3,"Review","Active"))))) -> Expired | AB13: =IF($F13="","",IF($X13="","",IF($Y13<0,"Past EOL",IF($Y13<=Settings!$B$4,"EOL soon","Supported")))) | AC13: =IF($F13="","",IF(OR($AA13="Expired",$AA13="Urgent",$AB13="Past EOL",$AB13="EOL soon"),"Yes","No")) -> Yes | AD13: TAM | AE13: 46118
A14: CPC | B14: HQ | C14: Other | D14: License | E14: Stack-X | F14: Automation and Orchestration | G14: TBC | H14: Production | I14: OPS Team | J14: Mostafa Mohamed | K14: TBC | L14: 45471 | M14: 45835 | N14: =IF($F14="","",IF($M14="","",$M14-TODAY())) -> -305 | O14: Annual | P14: No | Q14: 50 | R14: 4 | S14: =IF($F14="","",IF(OR($Q14="",$R14=""),"",$Q14-$R14)) -> 46 | T14: =IF($F14="","",IF(OR($Q14="",$Q14=0,$R14=""),"",$R14/$Q14)) -> 0.08 | V14: USD | W14: 2 | Y14: =IF($F14="","",IF($X14="","",$X14-TODAY())) | Z14: High | AA14: =IF($F14="","",IF($M14="","Missing expiry",IF($N14<0,"Expired",IF($N14<=Settings!$B$2,"Urgent",IF($N14<=Settings!$B$3,"Review","Active"))))) -> Expired | AB14: =IF($F14="","",IF($X14="","",IF($Y14<0,"Past EOL",IF($Y14<=Settings!$B$4,"EOL soon","Supported")))) | AC14: =IF($F14="","",IF(OR($AA14="Expired",$AA14="Urgent",$AB14="Past EOL",$AB14="EOL soon"),"Yes","No")) -> Yes | AD14: TAM | AE14: 46118
A15: CPC | B15: HQ | C15: Other | D15: License | E15: Stack-X | F15: Reporter | G15: TBC | H15: Production | I15: OPS Team | J15: Mostafa Mohamed | K15: TBC | L15: 45471 | M15: 45835 | N15: =IF($F15="","",IF($M15="","",$M15-TODAY())) -> -305 | O15: Annual | P15: No | Q15: 50 | R15: 0 | S15: =IF($F15="","",IF(OR($Q15="",$R15=""),"",$Q15-$R15)) -> 50 | T15: =IF($F15="","",IF(OR($Q15="",$Q15=0,$R15=""),"",$R15/$Q15)) -> 0 | U15: 2 | V15: USD | W15: =IF($F15="","",IF(OR($U15="",$Q15=""),"",$U15*$Q15)) -> 100 | Y15: =IF($F15="","",IF($X15="","",$X15-TODAY())) | Z15: High | AA15: =IF($F15="","",IF($M15="","Missing expiry",IF($N15<0,"Expired",IF($N15<=Settings!$B$2,"Urgent",IF($N15<=Settings!$B$3,"Review","Active"))))) -> Expired | AB15: =IF($F15="","",IF($X15="","",IF($Y15<0,"Past EOL",IF($Y15<=Settings!$B$4,"EOL soon","Supported")))) | AC15: =IF($F15="","",IF(OR($AA15="Expired",$AA15="Urgent",$AB15="Past EOL",$AB15="EOL soon"),"Yes","No")) -> Yes | AD15: TAM | AE15: 46118
A16: CPC | B16: HQ | C16: Other | D16: License | E16: Stack-X | F16: Archiving System | G16: TBC | H16: Production | I16: OPS Team | J16: Yasser Shehwey | K16: TBC | L16: 45471 | M16: 45835 | N16: =IF($F16="","",IF($M16="","",$M16-TODAY())) -> -305 | O16: Annual | P16: No | Q16: 200 | R16: 0 | S16: =IF($F16="","",IF(OR($Q16="",$R16=""),"",$Q16-$R16)) -> 200 | T16: =IF($F16="","",IF(OR($Q16="",$Q16=0,$R16=""),"",$R16/$Q16)) -> 0 | U16: 5 | V16: USD | W16: =IF($F16="","",IF(OR($U16="",$Q16=""),"",$U16*$Q16)) -> 1000 | Y16: =IF($F16="","",IF($X16="","",$X16-TODAY())) | Z16: High | AA16: =IF($F16="","",IF($M16="","Missing expiry",IF($N16<0,"Expired",IF($N16<=Settings!$B$2,"Urgent",IF($N16<=Settings!$B$3,"Review","Active"))))) -> Expired | AB16: =IF($F16="","",IF($X16="","",IF($Y16<0,"Past EOL",IF($Y16<=Settings!$B$4,"EOL soon","Supported")))) | AC16: =IF($F16="","",IF(OR($AA16="Expired",$AA16="Urgent",$AB16="Past EOL",$AB16="EOL soon"),"Yes","No")) -> Yes | AD16: TAM | AE16: 46118
A17: MOE | B17: Roxy | C17: SSL Certificate | D17: Certificate | E17: DigiCert | F17: Public SSL wildcard | G17: *.MoE.Gov.EG | H17: Production | I17: OPS Team | J17: Moamen Sharaf | K17: CN=*.Moe.Gov.Eg | L17: 46116 | M17: 46314 | N17: =IF($F17="","",IF($M17="","",$M17-TODAY())) -> 174 | O17: Semi-Annual | P17: No | Q17: 1 | R17: 1 | S17: =IF($F17="","",IF(OR($Q17="",$R17=""),"",$Q17-$R17)) -> 0 | T17: =IF($F17="","",IF(OR($Q17="",$Q17=0,$R17=""),"",$R17/$Q17)) -> 1 | U17: 300 | V17: USD | W17: =IF($F17="","",IF(OR($U17="",$Q17=""),"",$U17*$Q17)) -> 300 | Y17: =IF($F17="","",IF($X17="","",$X17-TODAY())) | Z17: Critical | AA17: =IF($F17="","",IF($M17="","Missing expiry",IF($N17<0,"Expired",IF($N17<=Settings!$B$2,"Urgent",IF($N17<=Settings!$B$3,"Review","Active"))))) -> Active | AB17: =IF($F17="","",IF($X17="","",IF($Y17<0,"Past EOL",IF($Y17<=Settings!$B$4,"EOL soon","Supported")))) | AC17: =IF($F17="","",IF(OR($AA17="Expired",$AA17="Urgent",$AB17="Past EOL",$AB17="EOL soon"),"Yes","No")) -> No | AD17: Shahawey | AE17: 46118 | AF17: Public-facing certificate
A18: MOE | B18: Roxy | C18: SSL Certificate | D18: Certificate | E18: DigiCert | F18: Public SSL wildcard | G18: *.EMIS.Gov.EG | H18: Production | I18: OPS Team | J18: Moamen Sharaf | K18: CN=*.EMIS.Gov.Eg | L18: 45780 | M18: 46150 | N18: =IF($F18="","",IF($M18="","",$M18-TODAY())) -> 10 | O18: Annual | P18: No | Q18: 1 | R18: 1 | S18: =IF($F18="","",IF(OR($Q18="",$R18=""),"",$Q18-$R18)) -> 0 | T18: =IF($F18="","",IF(OR($Q18="",$Q18=0,$R18=""),"",$R18/$Q18)) -> 1 | U18: 300 | V18: USD | W18: =IF($F18="","",IF(OR($U18="",$Q18=""),"",$U18*$Q18)) -> 300 | Z18: Critical | AA18: =IF($F18="","",IF($M18="","Missing expiry",IF($N18<0,"Expired",IF($N18<=Settings!$B$2,"Urgent",IF($N18<=Settings!$B$3,"Review","Active"))))) -> Urgent | AB18: =IF($F18="","",IF($X18="","",IF($Y18<0,"Past EOL",IF($Y18<=Settings!$B$4,"EOL soon","Supported")))) | AC18: =IF($F18="","",IF(OR($AA18="Expired",$AA18="Urgent",$AB18="Past EOL",$AB18="EOL soon"),"Yes","No")) -> Yes | AD18: Shahawey | AE18: 46118 | AF18: Public-facing certificate
A19: CPC | B19: HQ | C19: Server Management | D19: License | E19: Dell iDRAC | F19: Dell iDRAC | H19: Production | I19: OPS Team | J19: Mostafa Mohamed | N19: =IF($F19="","",IF($M19="","",$M19-TODAY())) | S19: =IF($F19="","",IF(OR($Q19="",$R19=""),"",$Q19-$R19)) | T19: =IF($F19="","",IF(OR($Q19="",$Q19=0,$R19=""),"",$R19/$Q19)) | W19: =IF($F19="","",IF(OR($U19="",$Q19=""),"",$U19*$Q19)) | AA19: =IF($F19="","",IF($M19="","Missing expiry",IF($N19<0,"Expired",IF($N19<=Settings!$B$2,"Urgent",IF($N19<=Settings!$B$3,"Review","Active"))))) -> Missing expiry | AB19: =IF($F19="","",IF($X19="","",IF($Y19<0,"Past EOL",IF($Y19<=Settings!$B$4,"EOL soon","Supported")))) | AC19: =IF($F19="","",IF(OR($AA19="Expired",$AA19="Urgent",$AB19="Past EOL",$AB19="EOL soon"),"Yes","No")) -> No
A20: CPC | B20: HQ | C20: Server Management | D20: License | E20: HP iLO | F20: HP Ilo | H20: Production | I20: OPS Team | J20: Mostafa Mohamed | N20: =IF($F20="","",IF($M20="","",$M20-TODAY())) | S20: =IF($F20="","",IF(OR($Q20="",$R20=""),"",$Q20-$R20)) | T20: =IF($F20="","",IF(OR($Q20="",$Q20=0,$R20=""),"",$R20/$Q20)) | W20: =IF($F20="","",IF(OR($U20="",$Q20=""),"",$U20*$Q20)) | AA20: =IF($F20="","",IF($M20="","Missing expiry",IF($N20<0,"Expired",IF($N20<=Settings!$B$2,"Urgent",IF($N20<=Settings!$B$3,"Review","Active"))))) -> Missing expiry | AB20: =IF($F20="","",IF($X20="","",IF($Y20<0,"Past EOL",IF($Y20<=Settings!$B$4,"EOL soon","Supported")))) | AC20: =IF($F20="","",IF(OR($AA20="Expired",$AA20="Urgent",$AB20="Past EOL",$AB20="EOL soon"),"Yes","No")) -> No
A21: ECMI | B21: ECMI (GOMCO/EPTIC) | C21: Monitoring | D21: License | E21: OpenText | F21: OBM | H21: Production | I21: OPS Team | L21: 46059 | M21: 46424 | N21: =IF($F21="","",IF($M21="","",$M21-TODAY())) -> 284 | O21: Annual | P21: No | Q21: 80 | R21: 420 | S21: =IF($F21="","",IF(OR($Q21="",$R21=""),"",$Q21-$R21)) -> -340 | T21: =IF($F21="","",IF(OR($Q21="",$Q21=0,$R21=""),"",$R21/$Q21)) -> 5.25 | AA21: =IF($F21="","",IF($M21="","Missing expiry",IF($N21<0,"Expired",IF($N21<=Settings!$B$2,"Urgent",IF($N21<=Settings!$B$3,"Review","Active"))))) -> Active | AB21: =IF($F21="","",IF($X21="","",IF($Y21<0,"Past EOL",IF($Y21<=Settings!$B$4,"EOL soon","Supported")))) | AC21: =IF($F21="","",IF(OR($AA21="Expired",$AA21="Urgent",$AB21="Past EOL",$AB21="EOL soon"),"Yes","No")) -> No
A22: ECMI | B22: ECMI (GOMCO/EPTIC) | C22: Tickting Solution | D22: License | E22: OpenText | F22: SMAX | H22: Production | I22: OPS Team | L22: 46059 | M22: 46424 | N22: =IF($F22="","",IF($M22="","",$M22-TODAY())) -> 284 | O22: Annual | P22: No | Q22: 10 | R22: 10 | S22: =IF($F22="","",IF(OR($Q22="",$R22=""),"",$Q22-$R22)) -> 0 | T22: =IF($F22="","",IF(OR($Q22="",$Q22=0,$R22=""),"",$R22/$Q22)) -> 1 | AA22: =IF($F22="","",IF($M22="","Missing expiry",IF($N22<0,"Expired",IF($N22<=Settings!$B$2,"Urgent",IF($N22<=Settings!$B$3,"Review","Active"))))) -> Active | AB22: =IF($F22="","",IF($X22="","",IF($Y22<0,"Past EOL",IF($Y22<=Settings!$B$4,"EOL soon","Supported")))) | AC22: =IF($F22="","",IF(OR($AA22="Expired",$AA22="Urgent",$AB22="Past EOL",$AB22="EOL soon"),"Yes","No")) -> No
A23: ECMI | B23: ECMI (GOMCO/EPTIC) | C23: Monitoring | D23: License | E23: OpenText | F23: NOM | H23: Production | I23: OPS Team | L23: 46059 | M23: 46424 | N23: =IF($F23="","",IF($M23="","",$M23-TODAY())) -> 284 | O23: Annual | P23: No | Q23: 200 | R23: 198 | S23: =IF($F23="","",IF(OR($Q23="",$R23=""),"",$Q23-$R23)) -> 2 | T23: =IF($F23="","",IF(OR($Q23="",$Q23=0,$R23=""),"",$R23/$Q23)) -> 0.99 | W23: =IF($F23="","",IF(OR($U23="",$Q23=""),"",$U23*$Q23)) | Y23: =IF($F23="","",IF($X23="","",$X23-TODAY())) | AA23: =IF($F23="","",IF($M23="","Missing expiry",IF($N23<0,"Expired",IF($N23<=Settings!$B$2,"Urgent",IF($N23<=Settings!$B$3,"Review","Active"))))) -> Active | AB23: =IF($F23="","",IF($X23="","",IF($Y23<0,"Past EOL",IF($Y23<=Settings!$B$4,"EOL soon","Supported")))) | AC23: =IF($F23="","",IF(OR($AA23="Expired",$AA23="Urgent",$AB23="Past EOL",$AB23="EOL soon"),"Yes","No")) -> No
A24: ECMI | B24: ECMI (GOMCO/EPTIC) | C24: Monitoring | D24: License | E24: OpenText | F24: Vertica | H24: Production | I24: OPS Team | L24: 45694 | M24: 46059 | N24: =IF($F24="","",IF($M24="","",$M24-TODAY())) -> -81 | O24: Annual | P24: No | S24: =IF($F24="","",IF(OR($Q24="",$R24=""),"",$Q24-$R24)) | T24: =IF($F24="","",IF(OR($Q24="",$Q24=0,$R24=""),"",$R24/$Q24)) | W24: =IF($F24="","",IF(OR($U24="",$Q24=""),"",$U24*$Q24)) | Y24: =IF($F24="","",IF($X24="","",$X24-TODAY())) | AA24: =IF($F24="","",IF($M24="","Missing expiry",IF($N24<0,"Expired",IF($N24<=Settings!$B$2,"Urgent",IF($N24<=Settings!$B$3,"Review","Active"))))) -> Expired | AB24: =IF($F24="","",IF($X24="","",IF($Y24<0,"Past EOL",IF($Y24<=Settings!$B$4,"EOL soon","Supported")))) | AC24: =IF($F24="","",IF(OR($AA24="Expired",$AA24="Urgent",$AB24="Past EOL",$AB24="EOL soon"),"Yes","No")) -> Yes
A25: ECMI | B25: ECMI (GOMCO/EPTIC) | C25: Monitoring | D25: License | E25: OpenText | F25: SAM | H25: Production | I25: OPS Team | L25: 46059 | M25: 46424 | N25: =IF($F25="","",IF($M25="","",$M25-TODAY())) -> 284 | O25: Annual | P25: No | Q25: 100 | R25: 0 | S25: =IF($F25="","",IF(OR($Q25="",$R25=""),"",$Q25-$R25)) -> 100 | T25: =IF($F25="","",IF(OR($Q25="",$Q25=0,$R25=""),"",$R25/$Q25)) -> 0 | W25: =IF($F25="","",IF(OR($U25="",$Q25=""),"",$U25*$Q25)) | Y25: =IF($F25="","",IF($X25="","",$X25-TODAY())) | AA25: =IF($F25="","",IF($M25="","Missing expiry",IF($N25<0,"Expired",IF($N25<=Settings!$B$2,"Urgent",IF($N25<=Settings!$B$3,"Review","Active"))))) -> Active | AB25: =IF($F25="","",IF($X25="","",IF($Y25<0,"Past EOL",IF($Y25<=Settings!$B$4,"EOL soon","Supported")))) | AC25: =IF($F25="","",IF(OR($AA25="Expired",$AA25="Urgent",$AB25="Past EOL",$AB25="EOL soon"),"Yes","No")) -> No
A26: ECMI | B26: ECMI (GOMCO/EPTIC) | C26: Monitoring | D26: License | E26: OpenText | F26: UCMDB | H26: Production | I26: OPS Team | L26: 46059 | M26: 46424 | N26: =IF($F26="","",IF($M26="","",$M26-TODAY())) -> 284 | O26: Annual | P26: No | Q26: 100 | R26: 300 | S26: =IF($F26="","",IF(OR($Q26="",$R26=""),"",$Q26-$R26)) -> -200 | T26: =IF($F26="","",IF(OR($Q26="",$Q26=0,$R26=""),"",$R26/$Q26)) -> 3 | W26: =IF($F26="","",IF(OR($U26="",$Q26=""),"",$U26*$Q26)) | Y26: =IF($F26="","",IF($X26="","",$X26-TODAY())) | AA26: =IF($F26="","",IF($M26="","Missing expiry",IF($N26<0,"Expired",IF($N26<=Settings!$B$2,"Urgent",IF($N26<=Settings!$B$3,"Review","Active"))))) -> Active | AB26: =IF($F26="","",IF($X26="","",IF($Y26<0,"Past EOL",IF($Y26<=Settings!$B$4,"EOL soon","Supported")))) | AC26: =IF($F26="","",IF(OR($AA26="Expired",$AA26="Urgent",$AB26="Past EOL",$AB26="EOL soon"),"Yes","No")) -> No
A27: ECMI | B27: ECMI (GOMCO/EPTIC) | C27: Stack-X | D27: License | E27: Elastic | F27: Elastic Backend | H27: Production | I27: OPS Team | L27: 46132 | M27: 46496 | N27: =IF($F27="","",IF($M27="","",$M27-TODAY())) -> 356 | O27: Annual | P27: No | Q27: 3 | R27: 3 | S27: =IF($F27="","",IF(OR($Q27="",$R27=""),"",$Q27-$R27)) -> 0 | T27: =IF($F27="","",IF(OR($Q27="",$Q27=0,$R27=""),"",$R27/$Q27)) -> 1 | W27: =IF($F27="","",IF(OR($U27="",$Q27=""),"",$U27*$Q27)) | AA27: =IF($F27="","",IF($M27="","Missing expiry",IF($N27<0,"Expired",IF($N27<=Settings!$B$2,"Urgent",IF($N27<=Settings!$B$3,"Review","Active"))))) -> Active | AC27: =IF($F27="","",IF(OR($AA27="Expired",$AA27="Urgent",$AB27="Past EOL",$AB27="EOL soon"),"Yes","No")) -> No
A28: ECMI | B28: ECMI (GOMCO/EPTIC) | C28: Endpoint Security | D28: License | E28: Elastic | F28: EDR | H28: Production | I28: OPS Team | L28: 46059 | M28: 46424 | N28: =IF($F28="","",IF($M28="","",$M28-TODAY())) -> 284 | O28: Annual | P28: No | Q28: 2750 | R28: 2400 | S28: =IF($F28="","",IF(OR($Q28="",$R28=""),"",$Q28-$R28)) -> 350 | T28: =IF($F28="","",IF(OR($Q28="",$Q28=0,$R28=""),"",$R28/$Q28)) -> 0.87272727 | W28: =IF($F28="","",IF(OR($U28="",$Q28=""),"",$U28*$Q28)) | Y28: =IF($F28="","",IF($X28="","",$X28-TODAY())) | AA28: =IF($F28="","",IF($M28="","Missing expiry",IF($N28<0,"Expired",IF($N28<=Settings!$B$2,"Urgent",IF($N28<=Settings!$B$3,"Review","Active"))))) -> Active | AB28: =IF($F28="","",IF($X28="","",IF($Y28<0,"Past EOL",IF($Y28<=Settings!$B$4,"EOL soon","Supported")))) | AC28: =IF($F28="","",IF(OR($AA28="Expired",$AA28="Urgent",$AB28="Past EOL",$AB28="EOL soon"),"Yes","No")) -> No
A29: ECMI | B29: ECMI (GOMCO/EPTIC) | C29: Endpoint Security | D29: License | E29: Elastic | F29: XDR | H29: Production | I29: OPS Team | L29: 46059 | M29: 46424 | N29: =IF($F29="","",IF($M29="","",$M29-TODAY())) -> 284 | O29: Annual | P29: No | S29: =IF($F29="","",IF(OR($Q29="",$R29=""),"",$Q29-$R29)) | T29: =IF($F29="","",IF(OR($Q29="",$Q29=0,$R29=""),"",$R29/$Q29)) | W29: =IF($F29="","",IF(OR($U29="",$Q29=""),"",$U29*$Q29)) | Y29: =IF($F29="","",IF($X29="","",$X29-TODAY())) | AA29: =IF($F29="","",IF($M29="","Missing expiry",IF($N29<0,"Expired",IF($N29<=Settings!$B$2,"Urgent",IF($N29<=Settings!$B$3,"Review","Active"))))) -> Active | AB29: =IF($F29="","",IF($X29="","",IF($Y29<0,"Past EOL",IF($Y29<=Settings!$B$4,"EOL soon","Supported")))) | AC29: =IF($F29="","",IF(OR($AA29="Expired",$AA29="Urgent",$AB29="Past EOL",$AB29="EOL soon"),"Yes","No")) -> No
A30: ECMI | B30: ECMI (GOMCO/EPTIC) | C30: Endpoint Security | D30: License | E30: Elastic | F30: NDR | H30: Production | I30: OPS Team | L30: 46059 | M30: 46424 | N30: =IF($F30="","",IF($M30="","",$M30-TODAY())) -> 284 | O30: Annual | P30: No | S30: =IF($F30="","",IF(OR($Q30="",$R30=""),"",$Q30-$R30)) | T30: =IF($F30="","",IF(OR($Q30="",$Q30=0,$R30=""),"",$R30/$Q30)) | W30: =IF($F30="","",IF(OR($U30="",$Q30=""),"",$U30*$Q30)) | Y30: =IF($F30="","",IF($X30="","",$X30-TODAY())) | AA30: =IF($F30="","",IF($M30="","Missing expiry",IF($N30<0,"Expired",IF($N30<=Settings!$B$2,"Urgent",IF($N30<=Settings!$B$3,"Review","Active"))))) -> Active | AB30: =IF($F30="","",IF($X30="","",IF($Y30<0,"Past EOL",IF($Y30<=Settings!$B$4,"EOL soon","Supported")))) | AC30: =IF($F30="","",IF(OR($AA30="Expired",$AA30="Urgent",$AB30="Past EOL",$AB30="EOL soon"),"Yes","No")) -> No
A31: ECMI | B31: ECMI (GOMCO/EPTIC) | C31: Monitoring | D31: License | E31: Elastic | F31: APM | H31: Production | I31: OPS Team | L31: 46059 | M31: 46424 | N31: =IF($F31="","",IF($M31="","",$M31-TODAY())) -> 284 | O31: Annual | P31: No | Q31: 10 | R31: 10 | S31: =IF($F31="","",IF(OR($Q31="",$R31=""),"",$Q31-$R31)) -> 0 | T31: =IF($F31="","",IF(OR($Q31="",$Q31=0,$R31=""),"",$R31/$Q31)) -> 1 | W31: =IF($F31="","",IF(OR($U31="",$Q31=""),"",$U31*$Q31)) | Y31: =IF($F31="","",IF($X31="","",$X31-TODAY())) | AA31: =IF($F31="","",IF($M31="","Missing expiry",IF($N31<0,"Expired",IF($N31<=Settings!$B$2,"Urgent",IF($N31<=Settings!$B$3,"Review","Active"))))) -> Active | AB31: =IF($F31="","",IF($X31="","",IF($Y31<0,"Past EOL",IF($Y31<=Settings!$B$4,"EOL soon","Supported")))) | AC31: =IF($F31="","",IF(OR($AA31="Expired",$AA31="Urgent",$AB31="Past EOL",$AB31="EOL soon"),"Yes","No")) -> No
A32: ECMI | B32: ECMI (GOMCO/EPTIC) | C32: Stack-X | D32: License | E32: Stack-X | F32: Automation and Orchestration | H32: Production | I32: OPS Team | L32: 46059 | M32: 46424 | N32: =IF($F32="","",IF($M32="","",$M32-TODAY())) -> 284 | O32: Annual | P32: No | Q32: 50 | R32: 5 | S32: =IF($F32="","",IF(OR($Q32="",$R32=""),"",$Q32-$R32)) -> 45 | T32: =IF($F32="","",IF(OR($Q32="",$Q32=0,$R32=""),"",$R32/$Q32)) -> 0.1 | W32: =IF($F32="","",IF(OR($U32="",$Q32=""),"",$U32*$Q32)) | Y32: =IF($F32="","",IF($X32="","",$X32-TODAY())) | AA32: =IF($F32="","",IF($M32="","Missing expiry",IF($N32<0,"Expired",IF($N32<=Settings!$B$2,"Urgent",IF($N32<=Settings!$B$3,"Review","Active"))))) -> Active | AB32: =IF($F32="","",IF($X32="","",IF($Y32<0,"Past EOL",IF($Y32<=Settings!$B$4,"EOL soon","Supported")))) | AC32: =IF($F32="","",IF(OR($AA32="Expired",$AA32="Urgent",$AB32="Past EOL",$AB32="EOL soon"),"Yes","No")) -> No
A33: ECMI | B33: ECMI (GOMCO/EPTIC) | C33: Stack-X | D33: License | E33: Stack-X | F33: EPM | H33: Production | I33: OPS Team | L33: 46059 | M33: 46424 | N33: =IF($F33="","",IF($M33="","",$M33-TODAY())) -> 284 | O33: Annual | P33: No | Q33: 2750 | R33: 0 | S33: =IF($F33="","",IF(OR($Q33="",$R33=""),"",$Q33-$R33)) -> 2750 | T33: =IF($F33="","",IF(OR($Q33="",$Q33=0,$R33=""),"",$R33/$Q33)) -> 0 | W33: =IF($F33="","",IF(OR($U33="",$Q33=""),"",$U33*$Q33)) | Y33: =IF($F33="","",IF($X33="","",$X33-TODAY())) | AA33: =IF($F33="","",IF($M33="","Missing expiry",IF($N33<0,"Expired",IF($N33<=Settings!$B$2,"Urgent",IF($N33<=Settings!$B$3,"Review","Active"))))) -> Active | AB33: =IF($F33="","",IF($X33="","",IF($Y33<0,"Past EOL",IF($Y33<=Settings!$B$4,"EOL soon","Supported")))) | AC33: =IF($F33="","",IF(OR($AA33="Expired",$AA33="Urgent",$AB33="Past EOL",$AB33="EOL soon"),"Yes","No")) -> No
A34: ECMI | B34: ECMI (GOMCO/EPTIC) | C34: Operating System | D34: License | E34: Microsoft | F34: MS 365 E3 | H34: Office | I34: OPS Team | L34: 45423.042 | M34: 46153.042 | N34: =IF($F34="","",IF($M34="","",$M34-TODAY())) -> 13.041667 | O34: Annual | P34: No | Q34: 100 | R34: 0 | S34: =IF($F34="","",IF(OR($Q34="",$R34=""),"",$Q34-$R34)) -> 100 | T34: =IF($F34="","",IF(OR($Q34="",$Q34=0,$R34=""),"",$R34/$Q34)) -> 0 | W34: =IF($F34="","",IF(OR($U34="",$Q34=""),"",$U34*$Q34)) | Y34: =IF($F34="","",IF($X34="","",$X34-TODAY())) | AA34: =IF($F34="","",IF($M34="","Missing expiry",IF($N34<0,"Expired",IF($N34<=Settings!$B$2,"Urgent",IF($N34<=Settings!$B$3,"Review","Active"))))) -> Urgent | AB34: =IF($F34="","",IF($X34="","",IF($Y34<0,"Past EOL",IF($Y34<=Settings!$B$4,"EOL soon","Supported")))) | AC34: =IF($F34="","",IF(OR($AA34="Expired",$AA34="Urgent",$AB34="Past EOL",$AB34="EOL soon"),"Yes","No")) -> Yes
A35: ECMI | B35: ECMI (GOMCO/EPTIC) | C35: Operating System | D35: License | E35: Microsoft | F35: Power BI Pro | H35: Office | I35: OPS Team | L35: 45423 | M35: 46153 | N35: =IF($F35="","",IF($M35="","",$M35-TODAY())) -> 13 | O35: Annual | P35: No | Q35: 10 | R35: 0 | S35: =IF($F35="","",IF(OR($Q35="",$R35=""),"",$Q35-$R35)) -> 10 | T35: =IF($F35="","",IF(OR($Q35="",$Q35=0,$R35=""),"",$R35/$Q35)) -> 0 | W35: =IF($F35="","",IF(OR($U35="",$Q35=""),"",$U35*$Q35)) | Y35: =IF($F35="","",IF($X35="","",$X35-TODAY())) | AA35: =IF($F35="","",IF($M35="","Missing expiry",IF($N35<0,"Expired",IF($N35<=Settings!$B$2,"Urgent",IF($N35<=Settings!$B$3,"Review","Active"))))) -> Urgent | AB35: =IF($F35="","",IF($X35="","",IF($Y35<0,"Past EOL",IF($Y35<=Settings!$B$4,"EOL soon","Supported")))) | AC35: =IF($F35="","",IF(OR($AA35="Expired",$AA35="Urgent",$AB35="Past EOL",$AB35="EOL soon"),"Yes","No")) -> Yes
A36: ECMI | B36: ECMI (GOMCO/EPTIC) | C36: Operating System | D36: License | E36: Microsoft | F36: Business Basic | H36: Office | I36: OPS Team | L36: 45423 | M36: 46153 | N36: =IF($F36="","",IF($M36="","",$M36-TODAY())) -> 13 | O36: Annual | P36: No | Q36: 90 | R36: 0 | S36: =IF($F36="","",IF(OR($Q36="",$R36=""),"",$Q36-$R36)) -> 90 | T36: =IF($F36="","",IF(OR($Q36="",$Q36=0,$R36=""),"",$R36/$Q36)) -> 0 | W36: =IF($F36="","",IF(OR($U36="",$Q36=""),"",$U36*$Q36)) | Y36: =IF($F36="","",IF($X36="","",$X36-TODAY())) | AA36: =IF($F36="","",IF($M36="","Missing expiry",IF($N36<0,"Expired",IF($N36<=Settings!$B$2,"Urgent",IF($N36<=Settings!$B$3,"Review","Active"))))) -> Urgent | AB36: =IF($F36="","",IF($X36="","",IF($Y36<0,"Past EOL",IF($Y36<=Settings!$B$4,"EOL soon","Supported")))) | AC36: =IF($F36="","",IF(OR($AA36="Expired",$AA36="Urgent",$AB36="Past EOL",$AB36="EOL soon"),"Yes","No")) -> Yes
A37: ECMI | B37: ECMI (GOMCO/EPTIC) | C37: Operating System | D37: License | E37: Microsoft | F37: Business Standard | H37: Office | I37: OPS Team | L37: 45423 | M37: 46153 | N37: =IF($F37="","",IF($M37="","",$M37-TODAY())) -> 13 | O37: Annual | P37: No | Q37: 300 | R37: 0 | S37: =IF($F37="","",IF(OR($Q37="",$R37=""),"",$Q37-$R37)) -> 300 | T37: =IF($F37="","",IF(OR($Q37="",$Q37=0,$R37=""),"",$R37/$Q37)) -> 0 | W37: =IF($F37="","",IF(OR($U37="",$Q37=""),"",$U37*$Q37)) | Y37: =IF($F37="","",IF($X37="","",$X37-TODAY())) | AA37: =IF($F37="","",IF($M37="","Missing expiry",IF($N37<0,"Expired",IF($N37<=Settings!$B$2,"Urgent",IF($N37<=Settings!$B$3,"Review","Active"))))) -> Urgent | AB37: =IF($F37="","",IF($X37="","",IF($Y37<0,"Past EOL",IF($Y37<=Settings!$B$4,"EOL soon","Supported")))) | AC37: =IF($F37="","",IF(OR($AA37="Expired",$AA37="Urgent",$AB37="Past EOL",$AB37="EOL soon"),"Yes","No")) -> Yes
A38: ECMI | B38: ECMI (GOMCO/EPTIC) | C38: Operating System | D38: License | E38: Microsoft | F38: MS 365 E5 | H38: Office | I38: OPS Team | L38: 45423 | M38: 46153 | N38: =IF($F38="","",IF($M38="","",$M38-TODAY())) -> 13 | O38: Annual | P38: No | Q38: 10 | R38: 0 | S38: =IF($F38="","",IF(OR($Q38="",$R38=""),"",$Q38-$R38)) -> 10 | T38: =IF($F38="","",IF(OR($Q38="",$Q38=0,$R38=""),"",$R38/$Q38)) -> 0 | W38: =IF($F38="","",IF(OR($U38="",$Q38=""),"",$U38*$Q38)) | Y38: =IF($F38="","",IF($X38="","",$X38-TODAY())) | AA38: =IF($F38="","",IF($M38="","Missing expiry",IF($N38<0,"Expired",IF($N38<=Settings!$B$2,"Urgent",IF($N38<=Settings!$B$3,"Review","Active"))))) -> Urgent | AB38: =IF($F38="","",IF($X38="","",IF($Y38<0,"Past EOL",IF($Y38<=Settings!$B$4,"EOL soon","Supported")))) | AC38: =IF($F38="","",IF(OR($AA38="Expired",$AA38="Urgent",$AB38="Past EOL",$AB38="EOL soon"),"Yes","No")) -> Yes
A39: ECMI | B39: ECMI (GOMCO/EPTIC) | C39: Operating System | D39: License | E39: Microsoft | F39: MS 365 Apps 4 Buiness | H39: Office | I39: OPS Team | L39: 45423 | M39: 46153 | N39: =IF($F39="","",IF($M39="","",$M39-TODAY())) -> 13 | O39: Annual | P39: No | Q39: 300 | R39: 0 | S39: =IF($F39="","",IF(OR($Q39="",$R39=""),"",$Q39-$R39)) -> 300 | T39: =IF($F39="","",IF(OR($Q39="",$Q39=0,$R39=""),"",$R39/$Q39)) -> 0 | W39: =IF($F39="","",IF(OR($U39="",$Q39=""),"",$U39*$Q39)) | Y39: =IF($F39="","",IF($X39="","",$X39-TODAY())) | AA39: =IF($F39="","",IF($M39="","Missing expiry",IF($N39<0,"Expired",IF($N39<=Settings!$B$2,"Urgent",IF($N39<=Settings!$B$3,"Review","Active"))))) -> Urgent | AB39: =IF($F39="","",IF($X39="","",IF($Y39<0,"Past EOL",IF($Y39<=Settings!$B$4,"EOL soon","Supported")))) | AC39: =IF($F39="","",IF(OR($AA39="Expired",$AA39="Urgent",$AB39="Past EOL",$AB39="EOL soon"),"Yes","No")) -> Yes
A40: ECMI | B40: ECMI (GOMCO/EPTIC) | C40: Backup | D40: License | E40: Exagrade | F40: Backup Exagrade HW Support | H40: Production | I40: OPS Team | L40: 45768 | M40: 46863 | N40: =IF($F40="","",IF($M40="","",$M40-TODAY())) -> 723 | O40: Annual | P40: No | Q40: 1 | R40: 1 | S40: =IF($F40="","",IF(OR($Q40="",$R40=""),"",$Q40-$R40)) -> 0 | T40: =IF($F40="","",IF(OR($Q40="",$Q40=0,$R40=""),"",$R40/$Q40)) -> 1 | W40: =IF($F40="","",IF(OR($U40="",$Q40=""),"",$U40*$Q40)) | Y40: =IF($F40="","",IF($X40="","",$X40-TODAY()))
...

Sheet Settings
A1: Control / Threshold | B1: Value | C1: Purpose
A2: Urgent days threshold | B2: 30 | C2: Licenses expiring in this window are flagged Urgent
A3: Review days threshold | B3: 60 | C3: Licenses expiring in this window are flagged Review
A4: EOL soon threshold | B4: 90 | C4: Support / OS lifecycle window for proactive action
A5: Default reminder lead time | B5: 60 | C5: Suggested reminder lead time for renewals
A6: Base currency | B6: USD | C6: Reference currency for reporting
A7: Template version | B7: 1.0 | C7: Update if you add new columns or logic
A10: Legend
A11: Blue text / fill | B11: Editable user input
A12: Gray fill | B12: Formula / derived cells
A13: Orange / Red | B13: Review, urgent or expired attention needed
A14: Green | B14: Healthy / active status

Sheet Lists
A1: Category | B1: Item Type | C1: Environment | D1: Renewal Cycle | E1: Yes / No | F1: Priority | G1: Currency
A2: SSL Certificate | B2: License | C2: Production | D2: Monthly | E2: Yes | F2: Low | G2: USD
A3: Server Management | B3: Subscription | C3: DR | D3: Quarterly | E3: No | F3: Medium | G3: EUR
A4: Endpoint Security | B4: Certificate | C4: Test | D4: Semi-Annual | F4: High | G4: EGP
A5: Virtualization | B5: Support Contract | C5: UAT | D5: Annual | F5: Critical | G5: SAR
A6: Operating System | B6: Warranty | C6: Office | D6: Multi-Year | G6: AED
A7: Network Appliance | B7: EOL/Lifecycle | C7: Cloud | D7: One-Time | G7: GBP
A8: Backup | B8: Maintenance | C8: Branch | D8: N/A | G8: Other
A9: Monitoring | B9: Domian Subscription | C9: Shared
A10: SaaS
A11: Stack-X
A12: Tickting Solution
A13: Other

Sheet How_to_Use
A1: How to Use the License & Subscription Tracker
A3: Managed Services best practice
A5: 1. Add one row per asset, license, certificate, subscription or OS lifecycle item in License_Register. | B5: Use the sample rows first, then replace with your real environment data.
A6: 2. Complete blue cells only. | B6: Gray cells calculate automatically: days to expiry, quantity availability, utilization, status and escalation.
A7: 3. Review the Dashboard daily or weekly. | B7: Prioritize Expired, Urgent, Review and Past EOL items for renewal planning.
A8: 4. Track quantities as well as dates. | B8: Useful for vCenter, Kaspersky, CALs, firewall bundles and any seat- or core-based licensing.
A9: 5. Use Support / EOL Date for lifecycle risk. | B9: This helps for OS versions, appliances, storage, switches and security products.
A10: 6. Update Last Reviewed after validation. | B10: Creates an audit trail and shows which records need re-checking.
A11: 7. Suggested operating rhythm. | B11: Assign an owner, review weekly, and discuss urgent rows in customer ops meetings.

Sheet Sheet1
E11: October | F11: SSL Certificate | G11: Certificate | H11: DigiCert | I11: Public SSL wildcard | J11: *.alpha-example.com | K11: Production | L11: NOC Team | M11: security@alpha.example | N11: CN=*.alpha-example.com | O11: 45823 | P11: 46188 | Q11: =IF($F11="","",IF($M11="","",$M11-TODAY())) -> #VALUE! | R11: Annual | S11: No | T11: 1 | U11: 1 | V11: =IF($F11="","",IF(OR($Q11="",$R11=""),"",$Q11-$R11)) -> #VALUE! | W11: =IF($F11="","",IF(OR($Q11="",$Q11=0,$R11=""),"",$R11/$Q11)) -> #VALUE! | X11: 0 | Y11: USD | Z11: =IF($F11="","",IF(OR($U11="",$Q11=""),"",$U11*$Q11)) -> #VALUE! | AB11: =IF($F11="","",IF($X11="","",$X11-TODAY())) -> -46140 | AC11: High | AD11: =IF($F11="","",IF($M11="","Missing expiry",IF($N11<0,"Expired",IF($N11<=Settings!$B$2,"Urgent",IF($N11<=Settings!$B$3,"Review","Active"))))) -> Active | AE11: =IF($F11="","",IF($X11="","",IF($Y11<0,"Past EOL",IF($Y11<=Settings!$B$4,"EOL soon","Supported")))) -> Supported | AF11: =IF($F11="","",IF(OR($AA11="Expired",$AA11="Urgent",$AB11="Past EOL",$AB11="EOL soon"),"Yes","No")) -> No | AG11: Security Lead | AH11: 46113 | AI11: Public-facing certificate | AJ11: https://portal.example/ssl
E12: Roxy | F12: Server Management | G12: License | H12: Dell | I12: iDRAC Enterprise | J12: esx-host-01 to 04 | K12: Production | L12: Infrastructure Team | M12: infra@beta.example | N12: IDRAC-ENT-2026 | O12: 45689 | P12: 46419 | Q12: =IF($F12="","",IF($M12="","",$M12-TODAY())) -> #VALUE! | R12: Annual | S12: No | T12: 4 | U12: 4 | V12: =IF($F12="","",IF(OR($Q12="",$R12=""),"",$Q12-$R12)) -> #VALUE! | W12: =IF($F12="","",IF(OR($Q12="",$Q12=0,$R12=""),"",$R12/$Q12)) -> #VALUE! | X12: 189 | Y12: USD | Z12: =IF($F12="","",IF(OR($U12="",$Q12=""),"",$U12*$Q12)) -> #VALUE! | AB12: =IF($F12="","",IF($X12="","",$X12-TODAY())) -> -45951 | AC12: Medium | AD12: =IF($F12="","",IF($M12="","Missing expiry",IF($N12<0,"Expired",IF($N12<=Settings!$B$2,"Urgent",IF($N12<=Settings!$B$3,"Review","Active"))))) -> Active | AE12: =IF($F12="","",IF($X12="","",IF($Y12<0,"Past EOL",IF($Y12<=Settings!$B$4,"EOL soon","Supported")))) -> Supported | AF12: =IF($F12="","",IF(OR($AA12="Expired",$AA12="Urgent",$AB12="Past EOL",$AB12="EOL soon"),"Yes","No")) -> No | AG12: Server Admin | AH12: 46106 | AI12: Per-host management license | AJ12: https://portal.example/idrac
E13: RDH | F13: Endpoint Security | G13: Subscription | H13: Kaspersky | I13: Kaspersky Endpoint Security | J13: Workstations & servers | K13: Shared | L13: SOC Team | M13: soc@gamma.example | N13: KASP-250-ENDP | O13: 45798 | P13: 46162 | Q13: =IF($F13="","",IF($M13="","",$M13-TODAY())) -> #VALUE! | R13: Annual | S13: Yes | T13: 250 | U13: 230 | V13: =IF($F13="","",IF(OR($Q13="",$R13=""),"",$Q13-$R13)) -> #VALUE! | W13: =IF($F13="","",IF(OR($Q13="",$Q13=0,$R13=""),"",$R13/$Q13)) -> #VALUE! | X13: 16.5 | Y13: USD | Z13: =IF($F13="","",IF(OR($U13="",$Q13=""),"",$U13*$Q13)) -> #VALUE! | AB13: =IF($F13="","",IF($X13="","",$X13-TODAY())) -> -46123.5 | AC13: Critical | AD13: =IF($F13="","",IF($M13="","Missing expiry",IF($N13<0,"Expired",IF($N13<=Settings!$B$2,"Urgent",IF($N13<=Settings!$B$3,"Review","Active"))))) -> Active | AE13: =IF($F13="","",IF($X13="","",IF($Y13<0,"Past EOL",IF($Y13<=Settings!$B$4,"EOL soon","Supported")))) -> Supported | AF13: =IF($F13="","",IF(OR($AA13="Expired",$AA13="Urgent",$AB13="Past EOL",$AB13="EOL soon"),"Yes","No")) -> No | AG13: Security Operations | AH13: 46111 | AI13: Track seat consumption monthly | AJ13: https://portal.example/kaspersky
E14: HQ | F14: Virtualization | G14: License | H14: VMware | I14: vCenter Server | J14: vcsa-prod-01 | K14: Production | L14: Platform Team | M14: vm@delta.example | N14: VCENTER-CPU-12 | O14: 45931 | P14: 46295 | Q14: =IF($F14="","",IF($M14="","",$M14-TODAY())) -> #VALUE! | R14: Annual | S14: No | T14: 12 | U14: 10 | V14: =IF($F14="","",IF(OR($Q14="",$R14=""),"",$Q14-$R14)) -> #VALUE! | W14: =IF($F14="","",IF(OR($Q14="",$Q14=0,$R14=""),"",$R14/$Q14)) -> #VALUE! | X14: 95 | Y14: USD | Z14: =IF($F14="","",IF(OR($U14="",$Q14=""),"",$U14*$Q14)) -> #VALUE! | AB14: =IF($F14="","",IF($X14="","",$X14-TODAY())) -> -46045 | AC14: High | AD14: =IF($F14="","",IF($M14="","Missing expiry",IF($N14<0,"Expired",IF($N14<=Settings!$B$2,"Urgent",IF($N14<=Settings!$B$3,"Review","Active"))))) -> Active | AE14: =IF($F14="","",IF($X14="","",IF($Y14<0,"Past EOL",IF($Y14<=Settings!$B$4,"EOL soon","Supported")))) -> Supported | AF14: =IF($F14="","",IF(OR($AA14="Expired",$AA14="Urgent",$AB14="Past EOL",$AB14="EOL soon"),"Yes","No")) -> No | AG14: Virtualization Lead | AH14: 46109 | AI14: Licensed by CPU count | AJ14: https://portal.example/vcenter
E15: Primary Site | F15: Operating System | G15: EOL/Lifecycle | H15: Microsoft | I15: Windows Server 2012 R2 | J15: app-legacy-01 | K15: Production | L15: Windows Team | M15: windows@epsilon.example | N15: WS2012R2-Lifecycle | O15: 43101 | Q15: =IF($F15="","",IF($M15="","",$M15-TODAY())) -> #VALUE! | R15: N/A | S15: No | T15: 1 | U15: 1 | V15: =IF($F15="","",IF(OR($Q15="",$R15=""),"",$Q15-$R15)) -> #VALUE! | W15: =IF($F15="","",IF(OR($Q15="",$Q15=0,$R15=""),"",$R15/$Q15)) -> #VALUE! | X15: 0 | Y15: USD | Z15: =IF($F15="","",IF(OR($U15="",$Q15=""),"",$U15*$Q15)) -> #VALUE! | AA15: 45209 | AB15: =IF($F15="","",IF($X15="","",$X15-TODAY())) -> -46140 | AC15: Critical | AD15: =IF($F15="","",IF($M15="","Missing expiry",IF($N15<0,"Expired",IF($N15<=Settings!$B$2,"Urgent",IF($N15<=Settings!$B$3,"Review","Active"))))) -> Active | AE15: =IF($F15="","",IF($X15="","",IF($Y15<0,"Past EOL",IF($Y15<=Settings!$B$4,"EOL soon","Supported")))) -> Supported | AF15: =IF($F15="","",IF(OR($AA15="Expired",$AA15="Urgent",$AB15="Past EOL",$AB15="EOL soon"),"Yes","No")) -> No | AG15: Infrastructure Manager | AH15: 46101 | AI15: Past vendor support; review migration | AJ15: https://learn.microsoft.com
E16: HQ | F16: Network Appliance | G16: Subscription | H16: Fortinet | I16: FortiGate UTM Bundle | J16: FG-100F-HQ | K16: Production | L16: Network Team | M16: network@zeta.example | N16: FGT-100F-UTM | O16: 45776 | P16: 46140 | Q16: =IF($F16="","",IF($M16="","",$M16-TODAY())) -> #VALUE! | R16: Annual | S16: No | T16: 1 | U16: 1 | V16: =IF($F16="","",IF(OR($Q16="",$R16=""),"",$Q16-$R16)) -> #VALUE! | W16: =IF($F16="","",IF(OR($Q16="",$Q16=0,$R16=""),"",$R16/$Q16)) -> #VALUE! | X16: 1250 | Y16: USD | Z16: =IF($F16="","",IF(OR($U16="",$Q16=""),"",$U16*$Q16)) -> #VALUE! | AA16: 46871 | AB16: =IF($F16="","",IF($X16="","",$X16-TODAY())) -> -44890 | AC16: High | AD16: =IF($F16="","",IF($M16="","Missing expiry",IF($N16<0,"Expired",IF($N16<=Settings!$B$2,"Urgent",IF($N16<=Settings!$B$3,"Review","Active"))))) -> Active | AE16: =IF($F16="","",IF($X16="","",IF($Y16<0,"Past EOL",IF($Y16<=Settings!$B$4,"EOL soon","Supported")))) -> Supported | AF16: =IF($F16="","",IF(OR($AA16="Expired",$AA16="Urgent",$AB16="Past EOL",$AB16="EOL soon"),"Yes","No")) -> No | AG16: Network Lead | AH16: 46114 | AI16: Renew early to avoid security signature lapse | AJ16: https://portal.example/fortigate
